2018-11-26 05:32:32,732 [WARNING]- Not Found: /
2018-11-26 06:18:04,770 [ERROR]- Internal Server Error: /query/results
Traceback (most recent call last):
  File "/home/rohittulu/.local/lib/python3.6/site-packages/django/db/backends/utils.py", line 85, in _execute
    return self.cursor.execute(sql, params)
  File "/home/rohittulu/.local/lib/python3.6/site-packages/django/db/backends/mysql/base.py", line 71, in execute
    return self.cursor.execute(query, args)
  File "/usr/lib/python3/dist-packages/MySQLdb/cursors.py", line 250, in execute
    self.errorhandler(self, exc, value)
  File "/usr/lib/python3/dist-packages/MySQLdb/connections.py", line 50, in defaulterrorhandler
    raise errorvalue
  File "/usr/lib/python3/dist-packages/MySQLdb/cursors.py", line 247, in execute
    res = self._query(query)
  File "/usr/lib/python3/dist-packages/MySQLdb/cursors.py", line 411, in _query
    rowcount = self._do_query(q)
  File "/usr/lib/python3/dist-packages/MySQLdb/cursors.py", line 374, in _do_query
    db.query(q)
  File "/usr/lib/python3/dist-packages/MySQLdb/connections.py", line 292, in query
    _mysql.connection.query(self, query)
_mysql_exceptions.ProgrammingError: (1064, "You have an error in your SQL syntax; check the manual that corresponds to your MySQL server version for the right syntax to use near 'selec' at line 1")

The above exception was the direct cause of the following exception:

Traceback (most recent call last):
  File "/home/rohittulu/.local/lib/python3.6/site-packages/django/core/handlers/exception.py", line 34, in inner
    response = get_response(request)
  File "/home/rohittulu/.local/lib/python3.6/site-packages/django/core/handlers/base.py", line 126, in _get_response
    response = self.process_exception_by_middleware(e, request)
  File "/home/rohittulu/.local/lib/python3.6/site-packages/django/core/handlers/base.py", line 124, in _get_response
    response = wrapped_callback(request, *callback_args, **callback_kwargs)
  File "/home/rohittulu/WikiApp/wiki/querymanager/views.py", line 28, in results
    return handle_page_query(request)
  File "/home/rohittulu/WikiApp/wiki/querymanager/handlers.py", line 18, in handle_page_query
    for page_obj in page_objs:
  File "/home/rohittulu/.local/lib/python3.6/site-packages/django/db/models/query.py", line 1339, in __iter__
    self._fetch_all()
  File "/home/rohittulu/.local/lib/python3.6/site-packages/django/db/models/query.py", line 1326, in _fetch_all
    self._result_cache = list(self.iterator())
  File "/home/rohittulu/.local/lib/python3.6/site-packages/django/db/models/query.py", line 1349, in iterator
    query = iter(self.query)
  File "/home/rohittulu/.local/lib/python3.6/site-packages/django/db/models/sql/query.py", line 96, in __iter__
    self._execute_query()
  File "/home/rohittulu/.local/lib/python3.6/site-packages/django/db/models/sql/query.py", line 130, in _execute_query
    self.cursor.execute(self.sql, params)
  File "/home/rohittulu/.local/lib/python3.6/site-packages/django/db/backends/utils.py", line 100, in execute
    return super().execute(sql, params)
  File "/home/rohittulu/.local/lib/python3.6/site-packages/django/db/backends/utils.py", line 68, in execute
    return self._execute_with_wrappers(sql, params, many=False, executor=self._execute)
  File "/home/rohittulu/.local/lib/python3.6/site-packages/django/db/backends/utils.py", line 77, in _execute_with_wrappers
    return executor(sql, params, many, context)
  File "/home/rohittulu/.local/lib/python3.6/site-packages/django/db/backends/utils.py", line 85, in _execute
    return self.cursor.execute(sql, params)
  File "/home/rohittulu/.local/lib/python3.6/site-packages/django/db/utils.py", line 89, in __exit__
    raise dj_exc_value.with_traceback(traceback) from exc_value
  File "/home/rohittulu/.local/lib/python3.6/site-packages/django/db/backends/utils.py", line 85, in _execute
    return self.cursor.execute(sql, params)
  File "/home/rohittulu/.local/lib/python3.6/site-packages/django/db/backends/mysql/base.py", line 71, in execute
    return self.cursor.execute(query, args)
  File "/usr/lib/python3/dist-packages/MySQLdb/cursors.py", line 250, in execute
    self.errorhandler(self, exc, value)
  File "/usr/lib/python3/dist-packages/MySQLdb/connections.py", line 50, in defaulterrorhandler
    raise errorvalue
  File "/usr/lib/python3/dist-packages/MySQLdb/cursors.py", line 247, in execute
    res = self._query(query)
  File "/usr/lib/python3/dist-packages/MySQLdb/cursors.py", line 411, in _query
    rowcount = self._do_query(q)
  File "/usr/lib/python3/dist-packages/MySQLdb/cursors.py", line 374, in _do_query
    db.query(q)
  File "/usr/lib/python3/dist-packages/MySQLdb/connections.py", line 292, in query
    _mysql.connection.query(self, query)
django.db.utils.ProgrammingError: (1064, "You have an error in your SQL syntax; check the manual that corresponds to your MySQL server version for the right syntax to use near 'selec' at line 1")
2018-11-26 06:23:50,455 [ERROR]- Internal Server Error: /query/results
Traceback (most recent call last):
  File "/home/rohittulu/.local/lib/python3.6/site-packages/django/core/handlers/exception.py", line 34, in inner
    response = get_response(request)
  File "/home/rohittulu/.local/lib/python3.6/site-packages/django/core/handlers/base.py", line 126, in _get_response
    response = self.process_exception_by_middleware(e, request)
  File "/home/rohittulu/.local/lib/python3.6/site-packages/django/core/handlers/base.py", line 124, in _get_response
    response = wrapped_callback(request, *callback_args, **callback_kwargs)
  File "/home/rohittulu/WikiApp/wiki/querymanager/views.py", line 28, in results
    return handle_page_query(request)
  File "/home/rohittulu/WikiApp/wiki/querymanager/handlers.py", line 36, in handle_page_query
    'time_taken': end_time - start_time
  File "/home/rohittulu/.local/lib/python3.6/site-packages/django/shortcuts.py", line 36, in render
    content = loader.render_to_string(template_name, context, request, using=using)
  File "/home/rohittulu/.local/lib/python3.6/site-packages/django/template/loader.py", line 62, in render_to_string
    return template.render(context, request)
  File "/home/rohittulu/.local/lib/python3.6/site-packages/django/template/backends/django.py", line 61, in render
    return self.template.render(context)
  File "/home/rohittulu/.local/lib/python3.6/site-packages/django/template/base.py", line 171, in render
    return self._render(context)
  File "/home/rohittulu/.local/lib/python3.6/site-packages/django/template/base.py", line 163, in _render
    return self.nodelist.render(context)
  File "/home/rohittulu/.local/lib/python3.6/site-packages/django/template/base.py", line 937, in render
    bit = node.render_annotated(context)
  File "/home/rohittulu/.local/lib/python3.6/site-packages/django/template/base.py", line 904, in render_annotated
    return self.render(context)
  File "/home/rohittulu/.local/lib/python3.6/site-packages/django/template/defaulttags.py", line 209, in render
    nodelist.append(node.render_annotated(context))
  File "/home/rohittulu/.local/lib/python3.6/site-packages/django/template/base.py", line 904, in render_annotated
    return self.render(context)
  File "/home/rohittulu/.local/lib/python3.6/site-packages/django/template/defaulttags.py", line 165, in render
    values = list(values)
TypeError: 'datetime.datetime' object is not iterable
2018-11-26 06:34:09,263 [ERROR]- Internal Server Error: /query/results
Traceback (most recent call last):
  File "/home/rohittulu/.local/lib/python3.6/site-packages/django/core/handlers/exception.py", line 34, in inner
    response = get_response(request)
  File "/home/rohittulu/.local/lib/python3.6/site-packages/django/core/handlers/base.py", line 126, in _get_response
    response = self.process_exception_by_middleware(e, request)
  File "/home/rohittulu/.local/lib/python3.6/site-packages/django/core/handlers/base.py", line 124, in _get_response
    response = wrapped_callback(request, *callback_args, **callback_kwargs)
  File "/home/rohittulu/WikiApp/wiki/querymanager/views.py", line 28, in results
    return handle_page_query(request)
  File "/home/rohittulu/WikiApp/wiki/querymanager/handlers.py", line 36, in handle_page_query
    'time_taken': end_time - start_time
  File "/home/rohittulu/.local/lib/python3.6/site-packages/django/shortcuts.py", line 36, in render
    content = loader.render_to_string(template_name, context, request, using=using)
  File "/home/rohittulu/.local/lib/python3.6/site-packages/django/template/loader.py", line 62, in render_to_string
    return template.render(context, request)
  File "/home/rohittulu/.local/lib/python3.6/site-packages/django/template/backends/django.py", line 61, in render
    return self.template.render(context)
  File "/home/rohittulu/.local/lib/python3.6/site-packages/django/template/base.py", line 171, in render
    return self._render(context)
  File "/home/rohittulu/.local/lib/python3.6/site-packages/django/template/base.py", line 163, in _render
    return self.nodelist.render(context)
  File "/home/rohittulu/.local/lib/python3.6/site-packages/django/template/base.py", line 937, in render
    bit = node.render_annotated(context)
  File "/home/rohittulu/.local/lib/python3.6/site-packages/django/template/base.py", line 904, in render_annotated
    return self.render(context)
  File "/home/rohittulu/.local/lib/python3.6/site-packages/django/template/defaulttags.py", line 209, in render
    nodelist.append(node.render_annotated(context))
  File "/home/rohittulu/.local/lib/python3.6/site-packages/django/template/base.py", line 904, in render_annotated
    return self.render(context)
  File "/home/rohittulu/.local/lib/python3.6/site-packages/django/template/defaulttags.py", line 165, in render
    values = list(values)
TypeError: 'datetime.datetime' object is not iterable
2018-11-26 06:36:17,481 [ERROR]- Internal Server Error: /query/results
Traceback (most recent call last):
  File "/home/rohittulu/.local/lib/python3.6/site-packages/django/core/handlers/exception.py", line 34, in inner
    response = get_response(request)
  File "/home/rohittulu/.local/lib/python3.6/site-packages/django/core/handlers/base.py", line 126, in _get_response
    response = self.process_exception_by_middleware(e, request)
  File "/home/rohittulu/.local/lib/python3.6/site-packages/django/core/handlers/base.py", line 124, in _get_response
    response = wrapped_callback(request, *callback_args, **callback_kwargs)
  File "/home/rohittulu/WikiApp/wiki/querymanager/views.py", line 28, in results
    return handle_page_query(request)
  File "/home/rohittulu/WikiApp/wiki/querymanager/handlers.py", line 36, in handle_page_query
    'time_taken': end_time - start_time
  File "/home/rohittulu/.local/lib/python3.6/site-packages/django/shortcuts.py", line 36, in render
    content = loader.render_to_string(template_name, context, request, using=using)
  File "/home/rohittulu/.local/lib/python3.6/site-packages/django/template/loader.py", line 62, in render_to_string
    return template.render(context, request)
  File "/home/rohittulu/.local/lib/python3.6/site-packages/django/template/backends/django.py", line 61, in render
    return self.template.render(context)
  File "/home/rohittulu/.local/lib/python3.6/site-packages/django/template/base.py", line 171, in render
    return self._render(context)
  File "/home/rohittulu/.local/lib/python3.6/site-packages/django/template/base.py", line 163, in _render
    return self.nodelist.render(context)
  File "/home/rohittulu/.local/lib/python3.6/site-packages/django/template/base.py", line 937, in render
    bit = node.render_annotated(context)
  File "/home/rohittulu/.local/lib/python3.6/site-packages/django/template/base.py", line 904, in render_annotated
    return self.render(context)
  File "/home/rohittulu/.local/lib/python3.6/site-packages/django/template/defaulttags.py", line 209, in render
    nodelist.append(node.render_annotated(context))
  File "/home/rohittulu/.local/lib/python3.6/site-packages/django/template/base.py", line 904, in render_annotated
    return self.render(context)
  File "/home/rohittulu/.local/lib/python3.6/site-packages/django/template/defaulttags.py", line 165, in render
    values = list(values)
TypeError: 'datetime.datetime' object is not iterable
2018-11-26 06:40:17,423 [ERROR]- Internal Server Error: /query/results
Traceback (most recent call last):
  File "/home/rohittulu/.local/lib/python3.6/site-packages/django/core/handlers/exception.py", line 34, in inner
    response = get_response(request)
  File "/home/rohittulu/.local/lib/python3.6/site-packages/django/core/handlers/base.py", line 126, in _get_response
    response = self.process_exception_by_middleware(e, request)
  File "/home/rohittulu/.local/lib/python3.6/site-packages/django/core/handlers/base.py", line 124, in _get_response
    response = wrapped_callback(request, *callback_args, **callback_kwargs)
  File "/home/rohittulu/WikiApp/wiki/querymanager/views.py", line 28, in results
    return handle_page_query(request)
  File "/home/rohittulu/WikiApp/wiki/querymanager/handlers.py", line 43, in handle_page_query
    'time_taken': end_time - start_time
  File "/home/rohittulu/.local/lib/python3.6/site-packages/django/shortcuts.py", line 36, in render
    content = loader.render_to_string(template_name, context, request, using=using)
  File "/home/rohittulu/.local/lib/python3.6/site-packages/django/template/loader.py", line 62, in render_to_string
    return template.render(context, request)
  File "/home/rohittulu/.local/lib/python3.6/site-packages/django/template/backends/django.py", line 61, in render
    return self.template.render(context)
  File "/home/rohittulu/.local/lib/python3.6/site-packages/django/template/base.py", line 171, in render
    return self._render(context)
  File "/home/rohittulu/.local/lib/python3.6/site-packages/django/template/base.py", line 163, in _render
    return self.nodelist.render(context)
  File "/home/rohittulu/.local/lib/python3.6/site-packages/django/template/base.py", line 937, in render
    bit = node.render_annotated(context)
  File "/home/rohittulu/.local/lib/python3.6/site-packages/django/template/base.py", line 904, in render_annotated
    return self.render(context)
  File "/home/rohittulu/.local/lib/python3.6/site-packages/django/template/defaulttags.py", line 209, in render
    nodelist.append(node.render_annotated(context))
  File "/home/rohittulu/.local/lib/python3.6/site-packages/django/template/base.py", line 904, in render_annotated
    return self.render(context)
  File "/home/rohittulu/.local/lib/python3.6/site-packages/django/template/defaulttags.py", line 165, in render
    values = list(values)
TypeError: 'datetime.datetime' object is not iterable
2018-11-26 06:45:11,860 [ERROR]- Internal Server Error: /query/results
Traceback (most recent call last):
  File "/home/rohittulu/.local/lib/python3.6/site-packages/django/core/handlers/exception.py", line 34, in inner
    response = get_response(request)
  File "/home/rohittulu/.local/lib/python3.6/site-packages/django/core/handlers/base.py", line 137, in _get_response
    "returned None instead." % (callback.__module__, view_name)
ValueError: The view querymanager.views.results didn't return an HttpResponse object. It returned None instead.
2018-11-26 08:37:24,493 [ERROR]- Internal Server Error: /get_most_outdated
Traceback (most recent call last):
  File "/home/rohittulu/.local/lib/python3.6/site-packages/django/core/handlers/exception.py", line 34, in inner
    response = get_response(request)
  File "/home/rohittulu/.local/lib/python3.6/site-packages/django/core/handlers/base.py", line 137, in _get_response
    "returned None instead." % (callback.__module__, view_name)
ValueError: The view querymanager.views.get_most_outdated didn't return an HttpResponse object. It returned None instead.
